Workbook

Sheet Information
B2: I flikar "ApteringsMax" och "PostningsMax" används färgerna nedan för indataval och resultat
C4: = Indatafält | E4: OBS! För att förhindra oavsiktliga formeländringar är filen låst
C5: = Resultatfält | E5: För att låsa upp är lösenordet: Sebastian5%Bonde
B7: ApteringsMax
B8: Används vid planering innan du åker till skogen eller på plats i skogen, innan du fäller och
B9: apterar för att optimera stockarna enl önskat sortiment.
B11: PostningsMax
B12: Används vid sågbänken för att optimera och förenkla upparbetning av stockarna till önskat
B13: sortiment
B15: Tabell Uttag - Block
B16: Används vid sågbänken för att enkelt och snabbt ta fram ett optimalt block för upparbetning av
B17: stockarna till önskat sortiment, dock utan stöd för sido- och ändbrädor/reglar. För den vane sågaren.
B19: Nedan ger jag förslag på sekvenssteg vid sågning av stock med Kedjesågverk.
B20: Om du väljer stockstorlek i flik "PostningsMax" får du rätt mått i figurerna.
C23: Steg 1
C24: Börja alltid med tänkta blockets långsida
C25: liggande horisontellt
C33: Steg 2
C34: Använd Postningsmallen och | F34: =IF(PostningsMax!C3="Välj från lista","",PostningsMax!C17/2) -> 4.25 | G34: FB/2
C35: sätt spiken på FB/2 från märgen eller | G35: =IF(PostningsMax!C3="Välj från lista","",PostningsMax!C9/2) -> 3
C36: det du väljer som stockens centrum. | G36: B/2
C37: Ska inga sidobrädor/reglar tas ut sätts
C38: spiken på B/2 från märgen eller det du
C39: väljer som stockens centrum.
C40: Gör första och resterande skär tills du nått ned till
C41: huvudblockets långsida
C58: Steg 3
C59: Vänd stocken 180°
C60: Lyft stockhyllan till stockskalan | F60: =IF(PostningsMax!C3="Välj från lista","",PostningsMax!C9/2+PostningsMax!C17/2) -> 7.25
C61: visar B/2+FB/2 eller om inga | F61: B/2+FB/2 | G61: =PostningsMax!C9 -> 6
C62: sidobrädor/reglar tas ut lyfts | G62: B
C63: den till den visar B.
C65: Gör första och resterande skär tills du nått ned till
C66: huvudblockets långsida
C78: Steg 4
C79: Vänd stocken 90°
C80: Använd Postningsmallen och | G80: =IF(PostningsMax!C3="Välj från lista","",PostningsMax!C18/2) -> 3.875 | J80: =IF(PostningsMax!C3="Välj från lista","",PostningsMax!C10/2) -> 3.875
C81: sätt spiken på FH/2 från märgen eller | G81: FH/2 | J81: H/2
C82: det du väljer som stockens centrum.
C83: Ska inga sidobrädor/reglar tas ut sätts
...

Sheet ApteringsMax
B3: ApteringsMax utan vankant | I3: =C5 -> 7 | K3: Bark
B4: Beskrivning | C4: Tum | E4: Milimeter | I4: (B)" | L4: =C6 -> 9.45 | M4: tum
B5: Blockbredd [B] | C5: 7 | D5: " | E5: =IF(C5="Välj från lista","",C5*25.4) -> 177.8 | F5: mm | L5: =E6 -> 24.003 | M5: cm
B6: Toppdiameter [pb] | C6: =IF(C5="Välj från lista","",_xlfn.FLOOR.MATH(SQRT((C5)^2+(C5)^2))*1.05) -> 9.45 | D6: " | E6: =IF(C5="Välj från lista","",C6*2.54) -> 24.003 | F6: cm | L6: (pb)
B7: Toppdiameter [fub] | C7: =IF(C5="Välj från lista","",_xlfn.FLOOR.MATH(SQRT((C5)^2+(C5)^2))) -> 9 | D7: " | E7: =IF(C5="Välj från lista","",C7*2.54) -> 22.86 | F7: cm
L8: Stockände (topp)
K11: Block
K13: =C7 -> 9 | L13: tum
K14: =E7 -> 22.86 | L14: cm
I15: Sågspår 1/4" | K15: (fub)
G16: Brädor/reglar

Sheet PostningsMax
I1: Eventuellt en eller flera
B2: Beskrivning | C2: Tum | E2: Milimeter | I2: sidobrädor/-reglar | L2: =C9 -> 6 | N2: Bark
B3: Diameter under bark [fub] | C3: 9.75 | D3: " | E3: =IF(C3="Välj från lista","",C3*25.4) -> 247.65 | F3: mm | L3: (B)" | O3: =IF(C3="Välj från lista","",C3) -> 9.75
O4: (fub)"
B7: OPTIMERING MAX UTTAG SORTIMENT 1 & 2" utan vankant | O7: Stockände (topp)
B8: Beskrivning | C8: Tum | E8: Milimeter | I8: =C10 -> 7.75 | J8: (H)"
B9: Blockbredd [B] | C9: =IF(C3="Välj från lista","",_xlfn.FLOOR.MATH(SQRT((C3/2)^2+(C3/2)^2))) -> 6 | D9: " | E9: =IF(C3="Välj från lista","",C9*25.4) -> 152.4 | F9: mm
B10: Blockhöjd [H] | C10: {=IF(C3="Välj från lista","",_xlfn.IFS(AND(Data!E4>=2,Data!E4<2.25),2,AND(Data!E4>=2.25,Data!E4<3.25),2.25,AND(Data!E4>=3.25,Data!E4<3.5),3.25,AND(Data!E4>=3.5,Data!E4<4.25),3.5,AND(Data!E4>=4.25,Data!E4<4.5),4.25,AND(Data!E4>=4.5,Data!E4<4.75),4.5,AND(Data!E4>=4.75,Data!E4<5.5),4.75,AND(Data!E4>=5.5,Data!E4<5.75),5.5,AND(Data!E4>=5.75,Data!E4<6),5.75,AND(Data!E4>=6,Data!E4<6.5),6,AND(Data!E4>=6.5,Data!E4<6.75),6.5,AND(Data!E4>=6.75,Data!E4<7),6.75,AND(Data!E4>=7,Data!E4<7.25),7,AND(Data!E4>=7.25,Data!E4<7.75),7.25,AND(Data!E4>=7.75,Data!E4<8),7.75,AND(Data!E4>=8,Data!E4<8.25),8,AND(Data!E4>=8.25,Data!E4<8.5),8.25,AND(Data!E4>=8.5,Data!E4<8.75),8.5,AND(Data!E4>=8.75,Data!E4<9),8.75,AND(Data!E4>=9,Data!E4<9.25),9,AND(Data!E4>=9.25,Data!E4<9.5),9.25,AND(Data!E4>=9.5,Data!E4<9.75),9.5,AND(Data!E4>=9.75,Data!E4<10),9.75,AND(Data!E4>=10,Data!E4<10.25),10,AND(Data!E4>=10.25,Data!E4<10.5),10.25,AND(Data!E4>=10.5,Data!E4<10.75),10.5,AND(Data!E4>=10.75,Data!E4<11),10.75,AND(Data!E4>=11,Data!E4<11.25),11,AND(Data!E4>=11.25,Data!E4<11.5),11.25,AND(Data!E4>=11.5,Data!E4<11.75),11.5,AND(Data!E4>=11.75,Data!E4<12),11.75,AND(Data!E4>=12,Data!E4<12.25),12,AND(Data!E4>=12.25,Data!E4<12.5),12.25,AND(Data!E4>=12.5,Data!E4<12.75),12.5,AND(Data!E4>=12.75,Data!E4<13),12.75,AND(Data!E4>=13,Data!E4<13.25),13,AND(Data!E4>=13.25,Data!E4<13.5),13.25,AND(Data!E4>=13.5,Data!E4<13.75),13.5,AND(Data!E4>=13.75,Data!E4<14),13.75,AND(Data!E4>=14,Data!E4<14.25),14,AND(Data!E4>=14.25,Data!E4<14.5),14.25,AND(Data!E4>=14.5,Data!E4<14.75),14.5,AND(Data!E4>=14.75,Data!E4<15),14.75,AND(Data!E4>=15,Data!E4<15.25),15))} -> 7.75 | D10: " | E10: =IF(C3="Välj från lista","",Data!E4*25.4) -> 197.82999 | F10: mm | N10: Block
B11: Antal 1" brädor | C11: =IF(C3="Välj från lista","",VLOOKUP(C10,Data!G3:I45,3,TRUE)) -> 1 | D11: st | E11: Block
B12: Antal 2" reglar/plank | C12: =IF(C3="Välj från lista","",VLOOKUP(C10,Data!G3:I45,2,TRUE)) -> 3 | D12: st | N12: Sågspår 1/4"
B13: Antal 1" brädor | C13: {=IF(C3="Välj från lista","",_xlfn.IFS(AND(Data!B3<1),0,AND(Data!B3>=1,Data!B3<2),2,AND(Data!B3>=2,Data!B3<3.75),0,AND(Data!B3>=3.75,Data!B3<4.75),2))} -> 0 | D13: st | E13: Ändbrädor/-reglar | I13: Eventuellt en eller flera
B14: Antal 2" reglar/plank | C14: {=IF(C3="Välj från lista","",_xlfn.IFS(AND(Data!B3<2),0,AND(Data!B3>=2,Data!B3<4.5),2,AND(Data!B3>=4.5,Data!B3<6.75),4,AND(Data!B3>=6.75,Data!B3<11),6))} -> 0 | D14: st | I14: änbrädor/-reglar | M14: Brädor/reglar i blocket
B15: Antal 1" brädor | C15: {=IF(C3="Välj från lista","",_xlfn.IFS(AND(Data!B4<1),0,AND(Data!B4>=1,Data!B4<2),2,AND(Data!B4>=2,Data!B4<3.75),0,AND(Data!B4>=3.75,Data!B4<4.75),2))} -> 2 | D15: st | E15: Sidobrädor/-reglar | L15: =C17 -> 8.5
B16: Antal 2" reglar/plank | C16: {=IF(C3="Välj från lista","",_xlfn.IFS(AND(Data!B4<2),0,AND(Data!B4>=2,Data!B4<4.5),2,AND(Data!B4>=4.5,Data!B4<6.75),4,AND(Data!B4>=6.75,Data!B4<11),6))} -> 0 | D16: st | L16: (FB)"
B17: Förblockbredd [FB] | C17: =IF(C3="Välj från lista","",C9+1.25*C15+2.25*C16) -> 8.5 | D17: " | E17: =IF(C3="Välj från lista","",C17*25.4) -> 215.9 | F17: mm
B18: Förblockhöjd [FH] | C18: =IF(C3="Välj från lista","",C10+1.25*C13+2.25*C14) -> 7.75 | D18: " | E18: =IF(C3="Välj från lista","",C18*25.4) -> 196.85 | F18: mm
I21: =C18 -> 7.75 | J21: (FH)"
I28: =IF(PostningsMax!C3="Välj från lista","",PostningsMax!C17/2) -> 4.25 | J28: FB/2
J29: =IF(PostningsMax!C3="Välj från lista","",PostningsMax!C9/2) -> 3
J30: B/2
I40: =IF(PostningsMax!C3="Välj från lista","",PostningsMax!K9/2+PostningsMax!C17/2) -> 4.25
I41: B/2+FB/2 | J41: =PostningsMax!C9 -> 6
J42: B
J48: =IF(PostningsMax!C3="Välj från lista","",PostningsMax!C18/2) -> 3.875 | M48: =IF(PostningsMax!C3="Välj från lista","",PostningsMax!C10/2) -> 3.875
J49: FH/2 | M49: H/2
I59: =IF(PostningsMax!C3="Välj från lista","",PostningsMax!C10/2+PostningsMax!C18/2) -> 7.75 | M59: =PostningsMax!C10 -> 7.75
I60: H/2+FH/2 | M60: H

Sheet Tabell Uttag - Block
A1: Uttag ["] (+=Sågspår=1/4") | E1: H=Blockhöjd ["] | I1: (B)"
A2: 2 | F2: 2 | K2: Stockände (topp)
A3: 1+1 | F3: 2.25
A4: 2+1 | F4: 3.25 | K4: Sågspår 1/4"
A5: 1+1+1 | F5: 3.5
A6: 2+2 | F6: 4.25 | G6: (H)"
A7: 2+1+1 | F7: 4.5
A8: 1+1+1+1 | F8: 4.75 | K8: Block
A9: 2+2+1 | F9: 5.5
A10: 2+1+1+1 | F10: 5.75
A11: 1+1+1+1+1 | F11: 6 | H11: Bark | J11: Brädor/reglar
A12: 2+2+2 | F12: 6.5
A13: 2+2+1+1 | F13: 6.75
A14: 2+1+1+1+1 | F14: 7
A15: 1+1+1+1+1+1 | F15: 7.25
A16: 2+2+2+1 | F16: 7.75
A17: 2+2+1+1+1 | F17: 8
A18: 2+1+1+1+1+1 | F18: 8.25
A19: 1+1+1+1+1+1+1 | F19: 8.5
A20: 2+2+2+2 | F20: 8.75
A21: 2+2+2+1+1 | F21: 9
A22: 2+2+1+1+1+1 | F22: 9.25
A23: 2+1+1+1+1+1+1 | F23: 9.5
... A44: 2+2+2+2+1+1+1+1+1 | F44: 15

Sheet Data
B1: Beräkning ämne till | E1: Beräkning ämne till
B2: sid-/ändbrädor/reglar | E2: Block | G2: Blockhöjd | H2: 2" | I2: 1" | L2: Välj från lista | N2: Välj från lista
A3: Ände | B3: =IF(PostningsMax!C3="Välj från lista","",(PostningsMax!C3-PostningsMax!C10-1)/2) -> 0.5 | D3: B | E3: =IF(PostningsMax!C3="Välj från lista","",SQRT((PostningsMax!C3/2)^2+(PostningsMax!C3/2)^2)) -> 6.8942911 | G3: 2 | H3: 1 | I3: 0 | L3: 3 | N3: 2
A4: Sida | B4: =IF(PostningsMax!C3="Välj från lista","",(PostningsMax!C3-PostningsMax!C9-1)/2) -> 1.375 | D4: H | E4: =IF(PostningsMax!C3="Välj från lista","",(SQRT((PostningsMax!C3/2)^2+(PostningsMax!C3/2)^2))+(E3-PostningsMax!C9)) -> 7.7885822 | G4: 2.25 | H4: 0 | I4: 2 | L4: 3.25 | N4: 3
G5: 3.25 | H5: 1 | I5: 1 | L5: 3.5 | N5: 4
G6: 3.5 | H6: 0 | I6: 3 | L6: 3.75 | N6: 5
G7: 4.25 | H7: 2 | I7: 0 | L7: 4 | N7: 6
G8: 4.5 | H8: 1 | I8: 2 | L8: 4.25 | N8: 7
G9: 4.75 | H9: 0 | I9: 4 | L9: 4.5 | N9: 8
G10: 5.5 | H10: 2 | I10: 1 | L10: 4.75 | N10: 9
G11: 5.75 | H11: 1 | I11: 3 | L11: 5 | N11: 10
G12: 6 | H12: 0 | I12: 5 | L12: 5.25 | N12: 11
G13: 6.5 | H13: 3 | I13: 0 | L13: 5.5 | N13: 12
G14: 6.75 | H14: 2 | I14: 2 | L14: 5.75 | N14: 13
G15: 7 | H15: 1 | I15: 4 | L15: 6 | N15: 14
G16: 7.25 | H16: 0 | I16: 6 | L16: 6.25
G17: 7.75 | H17: 3 | I17: 1 | L17: 6.5
G18: 8 | H18: 2 | I18: 3 | L18: 6.75
G19: 8.25 | H19: 1 | I19: 5 | L19: 7
G20: 8.5 | H20: 0 | I20: 7 | L20: 7.25
G21: 8.75 | H21: 4 | I21: 0 | L21: 7.5
G22: 9 | H22: 3 | I22: 2 | L22: 7.75
G23: 9.25 | H23: 2 | I23: 4 | L23: 8
G24: 9.5 | H24: 1 | I24: 6 | L24: 8.25
G25: 9.75 | H25: 0 | I25: 8 | L25: 8.5
G26: 10 | H26: 4 | I26: 1 | L26: 8.75
G27: 10.25 | H27: 3 | I27: 3 | L27: 9
... G29: 10.75 | H29: 1 | I29: 7 | L29: 9.5
A30: 2 | G30: 11 | H30: 5 | I30: 0 | L30: 9.75
A31: 0.25 | G31: 11.25 | H31: 4 | I31: 2 | L31: 10
A32: 2 | G32: 11.5 | H32: 3 | I32: 4 | L32: 10.25
A33: 0.25 | G33: 11.75 | H33: 2 | I33: 6 | L33: 10.5
A34: 2 | G34: 12.25 | H34: 5 | I34: 1 | L34: 10.75
A35: 0.25 | G35: 12.5 | H35: 4 | I35: 3 | L35: 11
A36: 2 | G36: 12.75 | H36: 3 | I36: 5 | L36: 11.25
A37: 0.25 | G37: 13 | H37: 2 | I37: 7 | L37: 11.5
A38: 2 | G38: 13.25 | H38: 6 | I38: 0 | L38: 11.75
A39: 0.25 | G39: 13.5 | H39: 5 | I39: 2 | L39: 12
A40: 2 | G40: 13.75 | H40: 4 | I40: 4 | L40: 12.25
A41: 0.25 | G41: 14 | H41: 3 | I41: 6 | L41: 12.5
...
